<?xml version="1.0" ?>
<!-- =================================================================================== -->
<!-- |    This document was autogenerated by xacro from my_robot.xacro                 | -->
<!-- |    EDITING THIS FILE BY HAND IS NOT RECOMMENDED                                 | -->
<!-- =================================================================================== -->
<robot name="robot" xmlns:xacro="http://ros.org/wiki/xacro">
  <!--build base link-->
  <link name="base_link">
    <visual>
      <geometry>
        <cylinder length="10" radius="120"/>
      </geometry>
      <origin xyz="0 0 0"/>
    </visual>
  </link>
  <!-- xarco property-->
  <!--xarco leg-->
  <!--build robot-->
  <joint name="leg1_coxa" type="revolute">
    <parent link="base_link"/>
    <child link="coxa1_link"/>
    <limit effort="10000" lower="-1.5" upper="1.5" velocity="100"/>
    <axis xyz="0 0 1"/>
    <origin rpy="0 0 0" xyz="0 -120 0 "/>
  </joint>
  <link name="coxa1_link">
    <visual>
      <geometry>
        <cylinder length="50" radius="10"/>
        <!--mesh filename="package://robot_discription/mesh/t2.STL"/-->
      </geometry>
      <origin rpy="1.57079632679  0 0" xyz="0 -25 0 "/>
      <material name="blue">
        <color rgba="0 0 .8 1"/>
      </material>
    </visual>
  </link>
  <joint name="femur1_joint" type="revolute">
    <parent link="coxa1_link"/>
    <child link="femur1_link"/>
    <limit effort="1000.0" lower="-1.57" upper="1.57" velocity="0.5"/>
    <axis xyz="1 0 0"/>
    <origin xyz="0 -50 0"/>
  </joint>
  <link name="femur1_link">
    <visual>
      <geometry>
        <cylinder length="120" radius="10"/>
      </geometry>
      <origin rpy="1.57 0 0" xyz="0 -60 0"/>
      <material name="blue">
        <color rgba="0 0 .8 1"/>
      </material>
    </visual>
  </link>
  <joint name="tibia1_joint" type="revolute">
    <parent link="femur1_link"/>
    <child link="tibia1_link"/>
    <limit effort="1000.0" lower="-2" upper="2" velocity="0.5"/>
    <axis xyz="1 0 0"/>
    <origin xyz="0 -120 0"/>
  </joint>
  <link name="tibia1_link">
    <visual>
      <geometry>
        <cylinder length="200" radius="10"/>
      </geometry>
      <origin rpy="1.57 0 0" xyz="0 -100 0"/>
      <material name="blue">
        <color rgba="0 0 .8 1"/>
      </material>
    </visual>
  </link>
  <joint name="leg2_coxa" type="revolute">
    <parent link="base_link"/>
    <child link="coxa2_link"/>
    <limit effort="10000" lower="-1.5" upper="1.5" velocity="100"/>
    <axis xyz="0 0 1"/>
    <origin rpy="0 0 -1.0471975512" xyz="-103.92 -60 0 "/>
  </joint>
  <link name="coxa2_link">
    <visual>
      <geometry>
        <cylinder length="50" radius="10"/>
        <!--mesh filename="package://robot_discription/mesh/t2.STL"/-->
      </geometry>
      <origin rpy="1.57079632679  0 0" xyz="0 -25 0 "/>
      <material name="blue">
        <color rgba="0 0 .8 1"/>
      </material>
    </visual>
  </link>
  <joint name="femur2_joint" type="revolute">
    <parent link="coxa2_link"/>
    <child link="femur2_link"/>
    <limit effort="1000.0" lower="-1.57" upper="1.57" velocity="0.5"/>
    <axis xyz="1 0 0"/>
    <origin xyz="0 -50 0"/>
  </joint>
  <link name="femur2_link">
    <visual>
      <geometry>
        <cylinder length="120" radius="10"/>
      </geometry>
      <origin rpy="1.57 0 0" xyz="0 -60 0"/>
      <material name="blue">
        <color rgba="0 0 .8 1"/>
      </material>
    </visual>
  </link>
  <joint name="tibia2_joint" type="revolute">
    <parent link="femur2_link"/>
    <child link="tibia2_link"/>
    <limit effort="1000.0" lower="-2" upper="2" velocity="0.5"/>
    <axis xyz="1 0 0"/>
    <origin xyz="0 -120 0"/>
  </joint>
  <link name="tibia2_link">
    <visual>
      <geometry>
        <cylinder length="200" radius="10"/>
      </geometry>
      <origin rpy="1.57 0 0" xyz="0 -100 0"/>
      <material name="blue">
        <color rgba="0 0 .8 1"/>
      </material>
    </visual>
  </link>
  <joint name="leg3_coxa" type="revolute">
    <parent link="base_link"/>
    <child link="coxa3_link"/>
    <limit effort="10000" lower="-1.5" upper="1.5" velocity="100"/>
    <axis xyz="0 0 1"/>
    <origin rpy="0 0 -2.09439510239" xyz="-103.92 60 0 "/>
  </joint>
  <link name="coxa3_link">
    <visual>
      <geometry>
        <cylinder length="50" radius="10"/>
        <!--mesh filename="package://robot_discription/mesh/t2.STL"/-->
      </geometry>
      <origin rpy="1.57079632679  0 0" xyz="0 -25 0 "/>
      <material name="blue">
        <color rgba="0 0 .8 1"/>
      </material>
    </visual>
  </link>
  <joint name="femur3_joint" type="revolute">
    <parent link="coxa3_link"/>
    <child link="femur3_link"/>
    <limit effort="1000.0" lower="-1.57" upper="1.57" velocity="0.5"/>
    <axis xyz="1 0 0"/>
    <origin xyz="0 -50 0"/>
  </joint>
  <link name="femur3_link">
    <visual>
      <geometry>
        <cylinder length="120" radius="10"/>
      </geometry>
      <origin rpy="1.57 0 0" xyz="0 -60 0"/>
      <material name="blue">
        <color rgba="0 0 .8 1"/>
      </material>
    </visual>
  </link>
  <joint name="tibia3_joint" type="revolute">
    <parent link="femur3_link"/>
    <child link="tibia3_link"/>
    <limit effort="1000.0" lower="-2" upper="2" velocity="0.5"/>
    <axis xyz="1 0 0"/>
    <origin xyz="0 -120 0"/>
  </joint>
  <link name="tibia3_link">
    <visual>
      <geometry>
        <cylinder length="200" radius="10"/>
      </geometry>
      <origin rpy="1.57 0 0" xyz="0 -100 0"/>
      <material name="blue">
        <color rgba="0 0 .8 1"/>
      </material>
    </visual>
  </link>
  <joint name="leg4_coxa" type="revolute">
    <parent link="base_link"/>
    <child link="coxa4_link"/>
    <limit effort="10000" lower="-1.5" upper="1.5" velocity="100"/>
    <axis xyz="0 0 1"/>
    <origin rpy="0 0 3.14159265359" xyz="0 120 0 "/>
  </joint>
  <link name="coxa4_link">
    <visual>
      <geometry>
        <cylinder length="50" radius="10"/>
        <!--mesh filename="package://robot_discription/mesh/t2.STL"/-->
      </geometry>
      <origin rpy="1.57079632679  0 0" xyz="0 -25 0 "/>
      <material name="blue">
        <color rgba="0 0 .8 1"/>
      </material>
    </visual>
  </link>
  <joint name="femur4_joint" type="revolute">
    <parent link="coxa4_link"/>
    <child link="femur4_link"/>
    <limit effort="1000.0" lower="-1.57" upper="1.57" velocity="0.5"/>
    <axis xyz="1 0 0"/>
    <origin xyz="0 -50 0"/>
  </joint>
  <link name="femur4_link">
    <visual>
      <geometry>
        <cylinder length="120" radius="10"/>
      </geometry>
      <origin rpy="1.57 0 0" xyz="0 -60 0"/>
      <material name="blue">
        <color rgba="0 0 .8 1"/>
      </material>
    </visual>
  </link>
  <joint name="tibia4_joint" type="revolute">
    <parent link="femur4_link"/>
    <child link="tibia4_link"/>
    <limit effort="1000.0" lower="-2" upper="2" velocity="0.5"/>
    <axis xyz="1 0 0"/>
    <origin xyz="0 -120 0"/>
  </joint>
  <link name="tibia4_link">
    <visual>
      <geometry>
        <cylinder length="200" radius="10"/>
      </geometry>
      <origin rpy="1.57 0 0" xyz="0 -100 0"/>
      <material name="blue">
        <color rgba="0 0 .8 1"/>
      </material>
    </visual>
  </link>
  <joint name="leg5_coxa" type="revolute">
    <parent link="base_link"/>
    <child link="coxa5_link"/>
    <limit effort="10000" lower="-1.5" upper="1.5" velocity="100"/>
    <axis xyz="0 0 1"/>
    <origin rpy="0 0 2.09439510239" xyz="103.92 60 0 "/>
  </joint>
  <link name="coxa5_link">
    <visual>
      <geometry>
        <cylinder length="50" radius="10"/>
        <!--mesh filename="package://robot_discription/mesh/t2.STL"/-->
      </geometry>
      <origin rpy="1.57079632679  0 0" xyz="0 -25 0 "/>
      <material name="blue">
        <color rgba="0 0 .8 1"/>
      </material>
    </visual>
  </link>
  <joint name="femur5_joint" type="revolute">
    <parent link="coxa5_link"/>
    <child link="femur5_link"/>
    <limit effort="1000.0" lower="-1.57" upper="1.57" velocity="0.5"/>
    <axis xyz="1 0 0"/>
    <origin xyz="0 -50 0"/>
  </joint>
  <link name="femur5_link">
    <visual>
      <geometry>
        <cylinder length="120" radius="10"/>
      </geometry>
      <origin rpy="1.57 0 0" xyz="0 -60 0"/>
      <material name="blue">
        <color rgba="0 0 .8 1"/>
      </material>
    </visual>
  </link>
  <joint name="tibia5_joint" type="revolute">
    <parent link="femur5_link"/>
    <child link="tibia5_link"/>
    <limit effort="1000.0" lower="-2" upper="2" velocity="0.5"/>
    <axis xyz="1 0 0"/>
    <origin xyz="0 -120 0"/>
  </joint>
  <link name="tibia5_link">
    <visual>
      <geometry>
        <cylinder length="200" radius="10"/>
      </geometry>
      <origin rpy="1.57 0 0" xyz="0 -100 0"/>
      <material name="blue">
        <color rgba="0 0 .8 1"/>
      </material>
    </visual>
  </link>
  <joint name="leg6_coxa" type="revolute">
    <parent link="base_link"/>
    <child link="coxa6_link"/>
    <limit effort="10000" lower="-1.5" upper="1.5" velocity="100"/>
    <axis xyz="0 0 1"/>
    <origin rpy="0 0 1.0471975512" xyz="103.92 -60 0 "/>
  </joint>
  <link name="coxa6_link">
    <visual>
      <geometry>
        <cylinder length="50" radius="10"/>
        <!--mesh filename="package://robot_discription/mesh/t2.STL"/-->
      </geometry>
      <origin rpy="1.57079632679  0 0" xyz="0 -25 0 "/>
      <material name="blue">
        <color rgba="0 0 .8 1"/>
      </material>
    </visual>
  </link>
  <joint name="femur6_joint" type="revolute">
    <parent link="coxa6_link"/>
    <child link="femur6_link"/>
    <limit effort="1000.0" lower="-1.57" upper="1.57" velocity="0.5"/>
    <axis xyz="1 0 0"/>
    <origin xyz="0 -50 0"/>
  </joint>
  <link name="femur6_link">
    <visual>
      <geometry>
        <cylinder length="120" radius="10"/>
      </geometry>
      <origin rpy="1.57 0 0" xyz="0 -60 0"/>
      <material name="blue">
        <color rgba="0 0 .8 1"/>
      </material>
    </visual>
  </link>
  <joint name="tibia6_joint" type="revolute">
    <parent link="femur6_link"/>
    <child link="tibia6_link"/>
    <limit effort="1000.0" lower="-2" upper="2" velocity="0.5"/>
    <axis xyz="1 0 0"/>
    <origin xyz="0 -120 0"/>
  </joint>
  <link name="tibia6_link">
    <visual>
      <geometry>
        <cylinder length="200" radius="10"/>
      </geometry>
      <origin rpy="1.57 0 0" xyz="0 -100 0"/>
      <material name="blue">
        <color rgba="0 0 .8 1"/>
      </material>
    </visual>
  </link>
</robot>
