<?xml version="1.0" ?>
<!-- =================================================================================== -->
<!-- |    This document was autogenerated by xacro from my_robot.xacro                 | -->
<!-- |    EDITING THIS FILE BY HAND IS NOT RECOMMENDED                                 | -->
<!-- =================================================================================== -->
<robot name="robot" xmlns:xacro="http://ros.org/wiki/xacro">
  <!--build base link-->
  <link name="base_link">
    <visual>
      <geometry>
        <cylinder length="10" radius="120"/>
      </geometry>
      <origin xyz="0 0 0"/>
    </visual>
  </link>
  <!-- xarco property-->
  <!--xarco leg-->
  <!--build robot-->
  <joint name="leg_coxa1" type="revolute">
    <parent link="base_link"/>
    <child link="coxa_link1"/>
    <limit effort="10000" lower="-1.5" upper="1.5" velocity="100"/>
    <axis xyz="0 0 1"/>
    <origin rpy="0 0 0" xyz="0 -120 0 "/>
  </joint>
  <link name="coxa_link1">
    <visual>
      <geometry>
        <cylinder length="50" radius="10"/>
        <!--mesh filename="package://robot_discription/mesh/t2.STL"/-->
      </geometry>
      <origin rpy="1.57079632679  0 0" xyz="0 -25 0 "/>
      <material name="blue">
        <color rgba="0 0 .8 1"/>
      </material>
    </visual>
  </link>
  <joint name="femur_joint1" type="revolute">
    <parent link="coxa_link1"/>
    <child link="femur_link1"/>
    <limit effort="1000.0" lower="-1.57" upper="1.57" velocity="0.5"/>
    <axis xyz="1 0 0"/>
    <origin xyz="0 -50 0"/>
  </joint>
  <link name="femur_link1">
    <visual>
      <geometry>
        <cylinder length="120" radius="10"/>
      </geometry>
      <origin rpy="1.57 0 0" xyz="0 -60 0"/>
      <material name="blue">
        <color rgba="0 0 .8 1"/>
      </material>
    </visual>
  </link>
  <joint name="tibia_joint1" type="revolute">
    <parent link="femur_link1"/>
    <child link="tibia_link1"/>
    <limit effort="1000.0" lower="-2" upper="2" velocity="0.5"/>
    <axis xyz="1 0 0"/>
    <origin xyz="0 -120 0"/>
  </joint>
  <link name="tibia_link1">
    <visual>
      <geometry>
        <cylinder length="200" radius="10"/>
      </geometry>
      <origin rpy="1.57 0 0" xyz="0 -100 0"/>
      <material name="blue">
        <color rgba="0 0 .8 1"/>
      </material>
    </visual>
  </link>
  <joint name="leg_coxa2" type="revolute">
    <parent link="base_link"/>
    <child link="coxa_link2"/>
    <limit effort="10000" lower="-1.5" upper="1.5" velocity="100"/>
    <axis xyz="0 0 1"/>
    <origin rpy="0 0 -1.0471975512" xyz="-103.92 -60 0 "/>
  </joint>
  <link name="coxa_link2">
    <visual>
      <geometry>
        <cylinder length="50" radius="10"/>
        <!--mesh filename="package://robot_discription/mesh/t2.STL"/-->
      </geometry>
      <origin rpy="1.57079632679  0 0" xyz="0 -25 0 "/>
      <material name="blue">
        <color rgba="0 0 .8 1"/>
      </material>
    </visual>
  </link>
  <joint name="femur_joint2" type="revolute">
    <parent link="coxa_link2"/>
    <child link="femur_link2"/>
    <limit effort="1000.0" lower="-1.57" upper="1.57" velocity="0.5"/>
    <axis xyz="1 0 0"/>
    <origin xyz="0 -50 0"/>
  </joint>
  <link name="femur_link2">
    <visual>
      <geometry>
        <cylinder length="120" radius="10"/>
      </geometry>
      <origin rpy="1.57 0 0" xyz="0 -60 0"/>
      <material name="blue">
        <color rgba="0 0 .8 1"/>
      </material>
    </visual>
  </link>
  <joint name="tibia_joint2" type="revolute">
    <parent link="femur_link2"/>
    <child link="tibia_link2"/>
    <limit effort="1000.0" lower="-2" upper="2" velocity="0.5"/>
    <axis xyz="1 0 0"/>
    <origin xyz="0 -120 0"/>
  </joint>
  <link name="tibia_link2">
    <visual>
      <geometry>
        <cylinder length="200" radius="10"/>
      </geometry>
      <origin rpy="1.57 0 0" xyz="0 -100 0"/>
      <material name="blue">
        <color rgba="0 0 .8 1"/>
      </material>
    </visual>
  </link>
  <joint name="leg_coxa3" type="revolute">
    <parent link="base_link"/>
    <child link="coxa_link3"/>
    <limit effort="10000" lower="-1.5" upper="1.5" velocity="100"/>
    <axis xyz="0 0 1"/>
    <origin rpy="0 0 -2.09439510239" xyz="-103.92 60 0 "/>
  </joint>
  <link name="coxa_link3">
    <visual>
      <geometry>
        <cylinder length="50" radius="10"/>
        <!--mesh filename="package://robot_discription/mesh/t2.STL"/-->
      </geometry>
      <origin rpy="1.57079632679  0 0" xyz="0 -25 0 "/>
      <material name="blue">
        <color rgba="0 0 .8 1"/>
      </material>
    </visual>
  </link>
  <joint name="femur_joint3" type="revolute">
    <parent link="coxa_link3"/>
    <child link="femur_link3"/>
    <limit effort="1000.0" lower="-1.57" upper="1.57" velocity="0.5"/>
    <axis xyz="1 0 0"/>
    <origin xyz="0 -50 0"/>
  </joint>
  <link name="femur_link3">
    <visual>
      <geometry>
        <cylinder length="120" radius="10"/>
      </geometry>
      <origin rpy="1.57 0 0" xyz="0 -60 0"/>
      <material name="blue">
        <color rgba="0 0 .8 1"/>
      </material>
    </visual>
  </link>
  <joint name="tibia_joint3" type="revolute">
    <parent link="femur_link3"/>
    <child link="tibia_link3"/>
    <limit effort="1000.0" lower="-2" upper="2" velocity="0.5"/>
    <axis xyz="1 0 0"/>
    <origin xyz="0 -120 0"/>
  </joint>
  <link name="tibia_link3">
    <visual>
      <geometry>
        <cylinder length="200" radius="10"/>
      </geometry>
      <origin rpy="1.57 0 0" xyz="0 -100 0"/>
      <material name="blue">
        <color rgba="0 0 .8 1"/>
      </material>
    </visual>
  </link>
  <joint name="leg_coxa4" type="revolute">
    <parent link="base_link"/>
    <child link="coxa_link4"/>
    <limit effort="10000" lower="-1.5" upper="1.5" velocity="100"/>
    <axis xyz="0 0 1"/>
    <origin rpy="0 0 3.14159265359" xyz="0 120 0 "/>
  </joint>
  <link name="coxa_link4">
    <visual>
      <geometry>
        <cylinder length="50" radius="10"/>
        <!--mesh filename="package://robot_discription/mesh/t2.STL"/-->
      </geometry>
      <origin rpy="1.57079632679  0 0" xyz="0 -25 0 "/>
      <material name="blue">
        <color rgba="0 0 .8 1"/>
      </material>
    </visual>
  </link>
  <joint name="femur_joint4" type="revolute">
    <parent link="coxa_link4"/>
    <child link="femur_link4"/>
    <limit effort="1000.0" lower="-1.57" upper="1.57" velocity="0.5"/>
    <axis xyz="1 0 0"/>
    <origin xyz="0 -50 0"/>
  </joint>
  <link name="femur_link4">
    <visual>
      <geometry>
        <cylinder length="120" radius="10"/>
      </geometry>
      <origin rpy="1.57 0 0" xyz="0 -60 0"/>
      <material name="blue">
        <color rgba="0 0 .8 1"/>
      </material>
    </visual>
  </link>
  <joint name="tibia_joint4" type="revolute">
    <parent link="femur_link4"/>
    <child link="tibia_link4"/>
    <limit effort="1000.0" lower="-2" upper="2" velocity="0.5"/>
    <axis xyz="1 0 0"/>
    <origin xyz="0 -120 0"/>
  </joint>
  <link name="tibia_link4">
    <visual>
      <geometry>
        <cylinder length="200" radius="10"/>
      </geometry>
      <origin rpy="1.57 0 0" xyz="0 -100 0"/>
      <material name="blue">
        <color rgba="0 0 .8 1"/>
      </material>
    </visual>
  </link>
  <joint name="leg_coxa5" type="revolute">
    <parent link="base_link"/>
    <child link="coxa_link5"/>
    <limit effort="10000" lower="-1.5" upper="1.5" velocity="100"/>
    <axis xyz="0 0 1"/>
    <origin rpy="0 0 2.09439510239" xyz="103.92 60 0 "/>
  </joint>
  <link name="coxa_link5">
    <visual>
      <geometry>
        <cylinder length="50" radius="10"/>
        <!--mesh filename="package://robot_discription/mesh/t2.STL"/-->
      </geometry>
      <origin rpy="1.57079632679  0 0" xyz="0 -25 0 "/>
      <material name="blue">
        <color rgba="0 0 .8 1"/>
      </material>
    </visual>
  </link>
  <joint name="femur_joint5" type="revolute">
    <parent link="coxa_link5"/>
    <child link="femur_link5"/>
    <limit effort="1000.0" lower="-1.57" upper="1.57" velocity="0.5"/>
    <axis xyz="1 0 0"/>
    <origin xyz="0 -50 0"/>
  </joint>
  <link name="femur_link5">
    <visual>
      <geometry>
        <cylinder length="120" radius="10"/>
      </geometry>
      <origin rpy="1.57 0 0" xyz="0 -60 0"/>
      <material name="blue">
        <color rgba="0 0 .8 1"/>
      </material>
    </visual>
  </link>
  <joint name="tibia_joint5" type="revolute">
    <parent link="femur_link5"/>
    <child link="tibia_link5"/>
    <limit effort="1000.0" lower="-2" upper="2" velocity="0.5"/>
    <axis xyz="1 0 0"/>
    <origin xyz="0 -120 0"/>
  </joint>
  <link name="tibia_link5">
    <visual>
      <geometry>
        <cylinder length="200" radius="10"/>
      </geometry>
      <origin rpy="1.57 0 0" xyz="0 -100 0"/>
      <material name="blue">
        <color rgba="0 0 .8 1"/>
      </material>
    </visual>
  </link>
  <joint name="leg_coxa6" type="revolute">
    <parent link="base_link"/>
    <child link="coxa_link6"/>
    <limit effort="10000" lower="-1.5" upper="1.5" velocity="100"/>
    <axis xyz="0 0 1"/>
    <origin rpy="0 0 1.0471975512" xyz="103.92 -60 0 "/>
  </joint>
  <link name="coxa_link6">
    <visual>
      <geometry>
        <cylinder length="50" radius="10"/>
        <!--mesh filename="package://robot_discription/mesh/t2.STL"/-->
      </geometry>
      <origin rpy="1.57079632679  0 0" xyz="0 -25 0 "/>
      <material name="blue">
        <color rgba="0 0 .8 1"/>
      </material>
    </visual>
  </link>
  <joint name="femur_joint6" type="revolute">
    <parent link="coxa_link6"/>
    <child link="femur_link6"/>
    <limit effort="1000.0" lower="-1.57" upper="1.57" velocity="0.5"/>
    <axis xyz="1 0 0"/>
    <origin xyz="0 -50 0"/>
  </joint>
  <link name="femur_link6">
    <visual>
      <geometry>
        <cylinder length="120" radius="10"/>
      </geometry>
      <origin rpy="1.57 0 0" xyz="0 -60 0"/>
      <material name="blue">
        <color rgba="0 0 .8 1"/>
      </material>
    </visual>
  </link>
  <joint name="tibia_joint6" type="revolute">
    <parent link="femur_link6"/>
    <child link="tibia_link6"/>
    <limit effort="1000.0" lower="-2" upper="2" velocity="0.5"/>
    <axis xyz="1 0 0"/>
    <origin xyz="0 -120 0"/>
  </joint>
  <link name="tibia_link6">
    <visual>
      <geometry>
        <cylinder length="200" radius="10"/>
      </geometry>
      <origin rpy="1.57 0 0" xyz="0 -100 0"/>
      <material name="blue">
        <color rgba="0 0 .8 1"/>
      </material>
    </visual>
  </link>
</robot>
