<?xml version="1.0" ?>
<!-- =================================================================================== -->
<!-- |    This document was autogenerated by xacro from /home/af/hexapod_ws/src/crab_proj/robot_discription/urdf/my_robotn4.xacro | -->
<!-- |    EDITING THIS FILE BY HAND IS NOT RECOMMENDED                                 | -->
<!-- =================================================================================== -->
<robot name="crab" xmlns:xacro="http://ros.org/wiki/xacro">
  <!-- Build the body frame -->
  <link name="base_link"/>
  <joint name="foot_tip_test" type="fixed">
    <parent link="base_link"/>
    <child link="foot_tip_test"/>
    <origin rpy="0 0 0" xyz="0 0 0"/>
  </joint>
  <link name="foot_tip_test">
    <visual>
      <origin rpy="0 0 0" xyz="250 0 -120"/>
      <geometry>
        <cylinder length="10" radius="10"/>
      </geometry>
      <material name="grey">
        <color rgba="0.5 0.5 0.5 1"/>
      </material>
    </visual>
  </link>
  <joint name="base_joint" type="fixed">
    <parent link="base_link"/>
    <child link="thorax"/>
    <origin rpy="0 0 0" xyz="0 0 0"/>
  </joint>
  <link name="thorax">
    <visual>
      <origin rpy="0 0 0" xyz="0 0 0"/>
      <geometry>
        <cylinder length="10" radius="100"/>
      </geometry>
      <material name="grey">
        <color rgba="0.5 0.5 0.5 1"/>
      </material>
    </visual>
  </link>
  <!-- Pi parameter -->
  <!-- Joint properties -->
  <!-- Leg macros -->
  <!-- Build robot model -->
  <!-- Build leg -->
  <joint name="leg_center_joint_r1" type="fixed">
    <origin rpy="0 0 0" xyz="86.6 -50 0"/>
    <parent link="thorax"/>
    <child link="leg_center_r1"/>
  </joint>
  <link name="leg_center_r1"/>
  <joint name="coxa_joint_r1" type="revolute">
    <origin rpy="0 0 -0.523598775598" xyz="0 0 0"/>
    <parent link="leg_center_r1"/>
    <child link="coxa_r1"/>
    <axis xyz="0 0 1"/>
    <limit effort="10000" lower="-1.9" upper="2.5" velocity="100"/>
  </joint>
  <!-- link: coxal1-->
  <link name="coxa_r1">
    <visual>
      <origin rpy="0 1.57079632679 0" xyz="25 0 0"/>
      <geometry>
        <cylinder length="50" radius="10"/>
      </geometry>
      <material name="">
        <color rgba="0.7 0.7 0 1"/>
      </material>
    </visual>
  </link>
  <joint name="femur_joint_r1" type="revolute">
    <origin rpy="-1.57079632679 0 0" xyz="50 0 0"/>
    <parent link="coxa_r1"/>
    <child link="femur_r1"/>
    <axis xyz="0 0 -1"/>
    <limit effort="10000" lower="-1.9" upper="2.5" velocity="100"/>
  </joint>
  <link name="femur_r1">
    <visual>
      <origin rpy="0 1.57079632679 0" xyz="40 0 0"/>
      <geometry>
        <cylinder length="80" radius="10"/>
      </geometry>
      <material name="">
        <color rgba="0 0.7 0.7 1"/>
      </material>
    </visual>
  </link>
  <joint name="tibia_joint_r1" type="revolute">
    <origin rpy="3.14159265359 0 1.57079632679" xyz="80 0 0"/>
    <parent link="femur_r1"/>
    <child link="tibia_r1"/>
    <axis xyz="0 0 1"/>
    <limit effort="10000" lower="-1.9" upper="2.5" velocity="100"/>
  </joint>
  <link name="tibia_r1">
    <visual>
      <origin rpy="0 1.57079632679 0" xyz="90 0 0"/>
      <geometry>
        <cylinder length="180" radius="10"/>
      </geometry>
      <material name="">
        <color rgba="0.7 0 0.7 1"/>
      </material>
    </visual>
  </link>
  <joint name="tibia_foot_joint_r1" type="fixed">
    <origin rpy="0 0 0" xyz="180 0 0"/>
    <parent link="tibia_r1"/>
    <child link="tibia_foot_r1"/>
  </joint>
  <link name="tibia_foot_r1"/>
  <!-- Build leg -->
  <joint name="leg_center_joint_r2" type="fixed">
    <origin rpy="0 0 0" xyz="0 -100 0"/>
    <parent link="thorax"/>
    <child link="leg_center_r2"/>
  </joint>
  <link name="leg_center_r2"/>
  <joint name="coxa_joint_r2" type="revolute">
    <origin rpy="0 0 -1.57079632679" xyz="0 0 0"/>
    <parent link="leg_center_r2"/>
    <child link="coxa_r2"/>
    <axis xyz="0 0 1"/>
    <limit effort="10000" lower="-1.9" upper="2.5" velocity="100"/>
  </joint>
  <!-- link: coxal1-->
  <link name="coxa_r2">
    <visual>
      <origin rpy="0 1.57079632679 0" xyz="25 0 0"/>
      <geometry>
        <cylinder length="50" radius="10"/>
      </geometry>
      <material name="">
        <color rgba="0.7 0.7 0 1"/>
      </material>
    </visual>
  </link>
  <joint name="femur_joint_r2" type="revolute">
    <origin rpy="-1.57079632679 0 0" xyz="50 0 0"/>
    <parent link="coxa_r2"/>
    <child link="femur_r2"/>
    <axis xyz="0 0 -1"/>
    <limit effort="10000" lower="-1.9" upper="2.5" velocity="100"/>
  </joint>
  <link name="femur_r2">
    <visual>
      <origin rpy="0 1.57079632679 0" xyz="40 0 0"/>
      <geometry>
        <cylinder length="80" radius="10"/>
      </geometry>
      <material name="">
        <color rgba="0 0.7 0.7 1"/>
      </material>
    </visual>
  </link>
  <joint name="tibia_joint_r2" type="revolute">
    <origin rpy="3.14159265359 0 1.57079632679" xyz="80 0 0"/>
    <parent link="femur_r2"/>
    <child link="tibia_r2"/>
    <axis xyz="0 0 1"/>
    <limit effort="10000" lower="-1.9" upper="2.5" velocity="100"/>
  </joint>
  <link name="tibia_r2">
    <visual>
      <origin rpy="0 1.57079632679 0" xyz="90 0 0"/>
      <geometry>
        <cylinder length="180" radius="10"/>
      </geometry>
      <material name="">
        <color rgba="0.7 0 0.7 1"/>
      </material>
    </visual>
  </link>
  <joint name="tibia_foot_joint_r2" type="fixed">
    <origin rpy="0 0 0" xyz="180 0 0"/>
    <parent link="tibia_r2"/>
    <child link="tibia_foot_r2"/>
  </joint>
  <link name="tibia_foot_r2"/>
  <!-- Build leg -->
  <joint name="leg_center_joint_r3" type="fixed">
    <origin rpy="0 0 0" xyz="-86.6 -50 0"/>
    <parent link="thorax"/>
    <child link="leg_center_r3"/>
  </joint>
  <link name="leg_center_r3"/>
  <joint name="coxa_joint_r3" type="revolute">
    <origin rpy="0 0 -2.61799387799" xyz="0 0 0"/>
    <parent link="leg_center_r3"/>
    <child link="coxa_r3"/>
    <axis xyz="0 0 1"/>
    <limit effort="10000" lower="-1.9" upper="2.5" velocity="100"/>
  </joint>
  <!-- link: coxal1-->
  <link name="coxa_r3">
    <visual>
      <origin rpy="0 1.57079632679 0" xyz="25 0 0"/>
      <geometry>
        <cylinder length="50" radius="10"/>
      </geometry>
      <material name="">
        <color rgba="0.7 0.7 0 1"/>
      </material>
    </visual>
  </link>
  <joint name="femur_joint_r3" type="revolute">
    <origin rpy="-1.57079632679 0 0" xyz="50 0 0"/>
    <parent link="coxa_r3"/>
    <child link="femur_r3"/>
    <axis xyz="0 0 -1"/>
    <limit effort="10000" lower="-1.9" upper="2.5" velocity="100"/>
  </joint>
  <link name="femur_r3">
    <visual>
      <origin rpy="0 1.57079632679 0" xyz="40 0 0"/>
      <geometry>
        <cylinder length="80" radius="10"/>
      </geometry>
      <material name="">
        <color rgba="0 0.7 0.7 1"/>
      </material>
    </visual>
  </link>
  <joint name="tibia_joint_r3" type="revolute">
    <origin rpy="3.14159265359 0 1.57079632679" xyz="80 0 0"/>
    <parent link="femur_r3"/>
    <child link="tibia_r3"/>
    <axis xyz="0 0 1"/>
    <limit effort="10000" lower="-1.9" upper="2.5" velocity="100"/>
  </joint>
  <link name="tibia_r3">
    <visual>
      <origin rpy="0 1.57079632679 0" xyz="90 0 0"/>
      <geometry>
        <cylinder length="180" radius="10"/>
      </geometry>
      <material name="">
        <color rgba="0.7 0 0.7 1"/>
      </material>
    </visual>
  </link>
  <joint name="tibia_foot_joint_r3" type="fixed">
    <origin rpy="0 0 0" xyz="180 0 0"/>
    <parent link="tibia_r3"/>
    <child link="tibia_foot_r3"/>
  </joint>
  <link name="tibia_foot_r3"/>
  <!-- Build leg -->
  <joint name="leg_center_joint_l1" type="fixed">
    <origin rpy="0 0 0" xyz="-86.6 50 0"/>
    <parent link="thorax"/>
    <child link="leg_center_l1"/>
  </joint>
  <link name="leg_center_l1"/>
  <joint name="coxa_joint_l1" type="revolute">
    <origin rpy="0 0 2.61799387799" xyz="0 0 0"/>
    <parent link="leg_center_l1"/>
    <child link="coxa_l1"/>
    <axis xyz="0 0 1"/>
    <limit effort="10000" lower="-1.9" upper="2.5" velocity="100"/>
  </joint>
  <!-- link: coxal1-->
  <link name="coxa_l1">
    <visual>
      <origin rpy="0 1.57079632679 0" xyz="25 0 0"/>
      <geometry>
        <cylinder length="50" radius="10"/>
      </geometry>
      <material name="">
        <color rgba="0.7 0.7 0 1"/>
      </material>
    </visual>
  </link>
  <joint name="femur_joint_l1" type="revolute">
    <origin rpy="-1.57079632679 0 0" xyz="50 0 0"/>
    <parent link="coxa_l1"/>
    <child link="femur_l1"/>
    <axis xyz="0 0 -1"/>
    <limit effort="10000" lower="-1.9" upper="2.5" velocity="100"/>
  </joint>
  <link name="femur_l1">
    <visual>
      <origin rpy="0 1.57079632679 0" xyz="40 0 0"/>
      <geometry>
        <cylinder length="80" radius="10"/>
      </geometry>
      <material name="">
        <color rgba="0 0.7 0.7 1"/>
      </material>
    </visual>
  </link>
  <joint name="tibia_joint_l1" type="revolute">
    <origin rpy="3.14159265359 0 1.57079632679" xyz="80 0 0"/>
    <parent link="femur_l1"/>
    <child link="tibia_l1"/>
    <axis xyz="0 0 1"/>
    <limit effort="10000" lower="-1.9" upper="2.5" velocity="100"/>
  </joint>
  <link name="tibia_l1">
    <visual>
      <origin rpy="0 1.57079632679 0" xyz="90 0 0"/>
      <geometry>
        <cylinder length="180" radius="10"/>
      </geometry>
      <material name="">
        <color rgba="0.7 0 0.7 1"/>
      </material>
    </visual>
  </link>
  <joint name="tibia_foot_joint_l1" type="fixed">
    <origin rpy="0 0 0" xyz="180 0 0"/>
    <parent link="tibia_l1"/>
    <child link="tibia_foot_l1"/>
  </joint>
  <link name="tibia_foot_l1"/>
  <!-- Build leg -->
  <joint name="leg_center_joint_l2" type="fixed">
    <origin rpy="0 0 0" xyz="0 100 0"/>
    <parent link="thorax"/>
    <child link="leg_center_l2"/>
  </joint>
  <link name="leg_center_l2"/>
  <joint name="coxa_joint_l2" type="revolute">
    <origin rpy="0 0 1.57079632679" xyz="0 0 0"/>
    <parent link="leg_center_l2"/>
    <child link="coxa_l2"/>
    <axis xyz="0 0 1"/>
    <limit effort="10000" lower="-1.9" upper="2.5" velocity="100"/>
  </joint>
  <!-- link: coxal1-->
  <link name="coxa_l2">
    <visual>
      <origin rpy="0 1.57079632679 0" xyz="25 0 0"/>
      <geometry>
        <cylinder length="50" radius="10"/>
      </geometry>
      <material name="">
        <color rgba="0.7 0.7 0 1"/>
      </material>
    </visual>
  </link>
  <joint name="femur_joint_l2" type="revolute">
    <origin rpy="-1.57079632679 0 0" xyz="50 0 0"/>
    <parent link="coxa_l2"/>
    <child link="femur_l2"/>
    <axis xyz="0 0 -1"/>
    <limit effort="10000" lower="-1.9" upper="2.5" velocity="100"/>
  </joint>
  <link name="femur_l2">
    <visual>
      <origin rpy="0 1.57079632679 0" xyz="40 0 0"/>
      <geometry>
        <cylinder length="80" radius="10"/>
      </geometry>
      <material name="">
        <color rgba="0 0.7 0.7 1"/>
      </material>
    </visual>
  </link>
  <joint name="tibia_joint_l2" type="revolute">
    <origin rpy="3.14159265359 0 1.57079632679" xyz="80 0 0"/>
    <parent link="femur_l2"/>
    <child link="tibia_l2"/>
    <axis xyz="0 0 1"/>
    <limit effort="10000" lower="-1.9" upper="2.5" velocity="100"/>
  </joint>
  <link name="tibia_l2">
    <visual>
      <origin rpy="0 1.57079632679 0" xyz="90 0 0"/>
      <geometry>
        <cylinder length="180" radius="10"/>
      </geometry>
      <material name="">
        <color rgba="0.7 0 0.7 1"/>
      </material>
    </visual>
  </link>
  <joint name="tibia_foot_joint_l2" type="fixed">
    <origin rpy="0 0 0" xyz="180 0 0"/>
    <parent link="tibia_l2"/>
    <child link="tibia_foot_l2"/>
  </joint>
  <link name="tibia_foot_l2"/>
  <!-- Build leg -->
  <joint name="leg_center_joint_l3" type="fixed">
    <origin rpy="0 0 0" xyz="86.6 50 0"/>
    <parent link="thorax"/>
    <child link="leg_center_l3"/>
  </joint>
  <link name="leg_center_l3"/>
  <joint name="coxa_joint_l3" type="revolute">
    <origin rpy="0 0 0.523598775598" xyz="0 0 0"/>
    <parent link="leg_center_l3"/>
    <child link="coxa_l3"/>
    <axis xyz="0 0 1"/>
    <limit effort="10000" lower="-1.9" upper="2.5" velocity="100"/>
  </joint>
  <!-- link: coxal1-->
  <link name="coxa_l3">
    <visual>
      <origin rpy="0 1.57079632679 0" xyz="25 0 0"/>
      <geometry>
        <cylinder length="50" radius="10"/>
      </geometry>
      <material name="">
        <color rgba="0.7 0.7 0 1"/>
      </material>
    </visual>
  </link>
  <joint name="femur_joint_l3" type="revolute">
    <origin rpy="-1.57079632679 0 0" xyz="50 0 0"/>
    <parent link="coxa_l3"/>
    <child link="femur_l3"/>
    <axis xyz="0 0 -1"/>
    <limit effort="10000" lower="-1.9" upper="2.5" velocity="100"/>
  </joint>
  <link name="femur_l3">
    <visual>
      <origin rpy="0 1.57079632679 0" xyz="40 0 0"/>
      <geometry>
        <cylinder length="80" radius="10"/>
      </geometry>
      <material name="">
        <color rgba="0 0.7 0.7 1"/>
      </material>
    </visual>
  </link>
  <joint name="tibia_joint_l3" type="revolute">
    <origin rpy="3.14159265359 0 1.57079632679" xyz="80 0 0"/>
    <parent link="femur_l3"/>
    <child link="tibia_l3"/>
    <axis xyz="0 0 1"/>
    <limit effort="10000" lower="-1.9" upper="2.5" velocity="100"/>
  </joint>
  <link name="tibia_l3">
    <visual>
      <origin rpy="0 1.57079632679 0" xyz="90 0 0"/>
      <geometry>
        <cylinder length="180" radius="10"/>
      </geometry>
      <material name="">
        <color rgba="0.7 0 0.7 1"/>
      </material>
    </visual>
  </link>
  <joint name="tibia_foot_joint_l3" type="fixed">
    <origin rpy="0 0 0" xyz="180 0 0"/>
    <parent link="tibia_l3"/>
    <child link="tibia_foot_l3"/>
  </joint>
  <link name="tibia_foot_l3"/>
</robot>
